<?xml version="1.0"?>
<robot
  name="robot1">
  <link
    name="base_link">
    <inertial>
      <origin
        xyz="0.028871 2.0101E-17 0.051026"
        rpy="0 0 0" />
      <mass
        value="0.32045" />
      <inertia
        ixx="0.00087592"
        ixy="3.705E-19"
        ixz="0.00019248"
        iyy="0.0026728"
        iyz="-5.2366E-20"
        izz="0.0034195" />
    </inertial>
    <visual>
      <origin
        xyz="0 0 0"
        rpy="0 0 0" />
      <geometry>
        <mesh
          filename="package://robot1/meshes/base_link.STL" />
      </geometry>
      <material
        name="">
        <color
          rgba="0.79216 0.81961 0.93333 1" />
        <texture
          filename="package://robot1/textures/red-paint-texture-1.jpg" />
      </material>
    </visual>
    <collision>
      <origin
        xyz="0 0 0"
        rpy="0 0 0" />
      <geometry>
        <mesh
          filename="package://robot1/meshes/base_link.STL" />
      </geometry>
    </collision>
  </link>
  <link
    name="right_wheel">
    <inertial>
      <origin
        xyz="0 3.4694E-18 0.015"
        rpy="0 0 0" />
      <mass
        value="0.1508" />
      <inertia
        ixx="7.1628E-05"
        ixy="-1.3324E-37"
        ixz="-3.0972E-21"
        iyy="7.1628E-05"
        iyz="-3.0459E-21"
        izz="0.00012064" />
    </inertial>
    <visual>
      <origin
        xyz="0 0 0"
        rpy="0 0 0" />
      <geometry>
        <mesh
          filename="package://robot1/meshes/right_wheel.STL" />
      </geometry>
      <material
        name="">
        <color
          rgba="0.79216 0.81961 0.93333 1" />
        <texture
          filename="package://robot1/textures/black.jpg" />
      </material>
    </visual>
    <collision>
      <origin
        xyz="0 0 0"
        rpy="0 0 0" />
      <geometry>
        <mesh
          filename="package://robot1/meshes/right_wheel.STL" />
      </geometry>
    </collision>
  </link>
  <joint
    name="right_wheel_joint"
    type="continuous">
    <origin
      xyz="-0.1 -0.105 0.04"
      rpy="1.5708 0 0" />
    <parent
      link="base_link" />
    <child
      link="right_wheel" />
    <axis
      xyz="0 0 -1" />
  </joint>
  <link
    name="left_wheel">
    <inertial>
      <origin
        xyz="0 3.4694E-18 0.015"
        rpy="0 0 0" />
      <mass
        value="0.1508" />
      <inertia
        ixx="7.1628E-05"
        ixy="-7.053E-38"
        ixz="1.5567E-37"
        iyy="7.1628E-05"
        iyz="5.8406E-21"
        izz="0.00012064" />
    </inertial>
    <visual>
      <origin
        xyz="0 0 0"
        rpy="0 0 0" />
      <geometry>
        <mesh
          filename="package://robot1/meshes/left_wheel.STL" />
      </geometry>
      <material
        name="">
        <color
          rgba="0.79216 0.81961 0.93333 1" />
        <texture
          filename="package://robot1/textures/black.jpg" />
      </material>
    </visual>
    <collision>
      <origin
        xyz="0 0 0"
        rpy="0 0 0" />
      <geometry>
        <mesh
          filename="package://robot1/meshes/left_wheel.STL" />
      </geometry>
    </collision>
  </link>
  <joint
    name="left_wheel_joint"
    type="continuous">
    <origin
      xyz="-0.1 0.105 0.04"
      rpy="1.5708 0 3.1416" />
    <parent
      link="base_link" />
    <child
      link="left_wheel" />
    <axis
      xyz="0 0 1" />
  </joint>
  <link
    name="Ultrasonic_right">
    <inertial>
      <origin
        xyz="0.00020929 -0.00010055 0.0040046"
        rpy="0 0 0" />
      <mass
        value="0.0045794" />
      <inertia
        ixx="9.0655E-07"
        ixy="-1.6888E-09"
        ixz="2.8633E-09"
        iyy="1.783E-07"
        iyz="-4.0519E-10"
        izz="9.5719E-07" />
    </inertial>
    <visual>
      <origin
        xyz="0 0 0"
        rpy="0 0 0" />
      <geometry>
        <mesh
          filename="package://robot1/meshes/Ultrasonic_right.STL" />
      </geometry>
      <material
        name="">
        <color
          rgba="1 1 1 1" />
      </material>
    </visual>
    <collision>
      <origin
        xyz="0 0 0"
        rpy="0 0 0" />
      <geometry>
        <mesh
          filename="package://robot1/meshes/Ultrasonic_right.STL" />
      </geometry>
    </collision>
  </link>
  <joint
    name="Ultrasonic_right_joint"
    type="fixed">
    <origin
      xyz="0.039741 -0.105 0.057582"
      rpy="1.5708 0 0" />
    <parent
      link="base_link" />
    <child
      link="Ultrasonic_right" />
    <axis
      xyz="0 0 0" />
  </joint>
  <link
    name="Ultrasonic_left">
    <inertial>
      <origin
        xyz="-0.00020929 0.00010055 0.0040046"
        rpy="0 0 0" />
      <mass
        value="0.0045794" />
      <inertia
        ixx="9.0655E-07"
        ixy="-1.6888E-09"
        ixz="-2.8633E-09"
        iyy="1.783E-07"
        iyz="4.0519E-10"
        izz="9.5719E-07" />
    </inertial>
    <visual>
      <origin
        xyz="0 0 0"
        rpy="0 0 0" />
      <geometry>
        <mesh
          filename="package://robot1/meshes/Ultrasonic_left.STL" />
      </geometry>
      <material
        name="">
        <color
          rgba="1 1 1 1" />
      </material>
    </visual>
    <collision>
      <origin
        xyz="0 0 0"
        rpy="0 0 0" />
      <geometry>
        <mesh
          filename="package://robot1/meshes/Ultrasonic_left.STL" />
      </geometry>
    </collision>
  </link>
  <joint
    name="Ultrasonic_left_joint"
    type="fixed">
    <origin
      xyz="0.039741 0.105 0.057418"
      rpy="1.5708 0 3.1416" />
    <parent
      link="base_link" />
    <child
      link="Ultrasonic_left" />
    <axis
      xyz="0 0 0" />
  </joint>


  <link
    name="lidar">
    <inertial>
      <origin
        xyz="0 0.01 1.6323E-18"
        rpy="0 0 0" />
      <mass
        value="0.025133" />
      <inertia
        ixx="3.351E-06"
        ixy="-9.7136E-39"
        ixz="-1.2745E-54"
        iyy="5.0265E-06"
        iyz="-2.112E-38"
        izz="3.351E-06" />
    </inertial>
    <visual>
      <origin
        xyz="0 0 0"
        rpy="0 0 0" />
      <geometry>
        <mesh
          filename="package://robot1/meshes/lidar.STL" />
      </geometry>
      <material
        name="">
        <color
          rgba="0.79216 0.81961 0.93333 1" />
      </material>
    </visual>
    <collision>
      <origin
        xyz="0 0 0"
        rpy="0 0 0" />
      <geometry>
        <mesh
          filename="package://robot1/meshes/lidar.STL" />
      </geometry>
    </collision>
  </link>
  <joint
    name="lidar_joint"
    type="fixed">
    <origin
      xyz="0.13 0 0.06"
      rpy="1.5708 0 0" />
    <parent
      link="base_link" />
    <child
      link="lidar" />
    <axis
      xyz="0 0 0" />
  </joint>
  <link
    name="right_sensor">
    <inertial>
      <origin
        xyz="0 0 1.3878E-17"
        rpy="0 0 0" />
      <mass
        value="1E-06" />
      <inertia
        ixx="1.6667E-13"
        ixy="8.7129E-46"
        ixz="5.416E-45"
        iyy="1.6667E-13"
        iyz="-6.8423E-46"
        izz="1.6667E-13" />
    </inertial>
    <visual>
      <origin
        xyz="0 0 0"
        rpy="0 0 0" />
      <geometry>
        <mesh
          filename="package://robot1/meshes/right_sensor.STL" />
      </geometry>
      <material
        name="">
        <color
          rgba="0.79216 0.81961 0.93333 1" />
      </material>
    </visual>
    <collision>
      <origin
        xyz="0 0 0"
        rpy="0 0 0" />
      <geometry>
        <mesh
          filename="package://robot1/meshes/right_sensor.STL" />
      </geometry>
    </collision>
  </link>
  <joint
    name="right_sensor_joint"
    type="fixed">
    <origin
      xyz="0.04 -0.106 0.058"
      rpy="1.5708 0 -1.5708" />
    <parent
      link="base_link" />
    <child
      link="right_sensor" />
    <axis
      xyz="0 0 0" />
  </joint>
  <link
    name="left_sensor">
    <inertial>
      <origin
        xyz="0 0 1.3878E-17"
        rpy="0 0 0" />
      <mass
        value="1E-06" />
      <inertia
        ixx="1.6667E-13"
        ixy="-8.7129E-46"
        ixz="5.4104E-45"
        iyy="1.6667E-13"
        iyz="6.8423E-46"
        izz="1.6667E-13" />
    </inertial>
    <visual>
      <origin
        xyz="0 0 0"
        rpy="0 0 0" />
      <geometry>
        <mesh
          filename="package://robot1/meshes/left_sensor.STL" />
      </geometry>
      <material
        name="">
        <color
          rgba="0.79216 0.81961 0.93333 1" />
      </material>
    </visual>
    <collision>
      <origin
        xyz="0 0 0"
        rpy="0 0 0" />
      <geometry>
        <mesh
          filename="package://robot1/meshes/left_sensor.STL" />
      </geometry>
    </collision>
  </link>
  <joint
    name="left_sensor_joint"
    type="fixed">
    <origin
      xyz="0.04 0.106 0.058"
      rpy="1.5708 0 1.5708" />
    <parent
      link="base_link" />
    <child
      link="left_sensor" />
    <axis
      xyz="0 0 0" />
  </joint>
  <!--link name="lidar_sensor">
    <inertial>
	<origin
        xyz="0 0.01 1.63232502450634E-18"
        rpy="0 0 0" />
      <mass
        value="1E-06" />
      <inertia
        ixx="1.6667E-13"
        ixy="2.0527E-45"
        ixz="-1.4892E-30"
        iyy="1.6667E-13"
        iyz="0"
        izz="1.6667E-13" />
    </inertial>
    <visual>
      <origin
        xyz="0 0 0"
        rpy="0 0 0" />
      <geometry>
        <mesh
          filename="package://robot1/meshes/lidar_sensor.STL" />
      </geometry>
      <material
        name="">
        <color
          rgba="0.79216 0.81961 0.93333 1" />
      </material>
    </visual>
    <collision>
      <origin
        xyz="0 0 0"
        rpy="0 0 0" />
      <geometry>
        <mesh
          filename="package://robot1/meshes/lidar_sensor.STL" />
      </geometry>
    </collision>
  </link>
  <joint
    name="lidar_joint1"
    type="fixed">
    <origin
      xyz="0.13 0 0.06"
      rpy="1.5708 0 0" />
    <parent
      link="base_link" />
    <child
      link="lidar_sensor" />
    <axis
      xyz="0 1 0" />
  </joint-->

  <link name="lidar_sensor">
    <inertial>
	<origin
        xyz="0 0.01 1.63232502450634E-18"
        rpy="0 0 0" />
      
      <mass
        value="1E-06" />
      <inertia
        ixx="1.6667E-13"
        ixy="2.0527E-45"
        ixz="-1.4892E-30"
        iyy="1.6667E-13"
        iyz="0"
        izz="1.6667E-13" />
    </inertial>
    <collision name="collision">
      <geometry>
        <box>
          <size>1 1 1</size>
        </box>
      </geometry>
     </collision>
    <visual name="collision">
      <geometry>
        <box>
          <size>1 1 1</size>
        </box>
      </geometry>
    </visual>
  </link>


  <joint
    name="lidar_joint1"
    type="fixed">
    <origin
      xyz="0.13 0 0.07"
      rpy="0 0 0" />
    <parent
      link="base_link" />
    <child
      link="lidar_sensor" />
    <axis
      xyz="0 1 0" />
  </joint>

<!--joint name="sonar_joint" type="fixed">
    <origin xyz="0.1 0 .01" rpy="0 0 0"/>
    <parent link="base_link" />
    <child link="sonar_link" />
</joint>

<link name="sonar_link" />



<joint name="sonar_joint_fake" type="fixed">
    <origin rpy="0 ${-pi/2} 0"/>
    <parent link="sonar_link" />
    <child link="sonar_link_fake" />
</joint>

<link name="sonar_link_fake"/-->



  <gazebo>
    <plugin filename="libgazebo_ros_diff_drive.so" name="differential_drive_controller">
      <alwaysOn>true</alwaysOn>
      <updateRate>20</updateRate>
      <legacyMode>true</legacyMode>
      <leftJoint>right_wheel_joint</leftJoint>
      <rightJoint>left_wheel_joint</rightJoint>
      <wheelSeparation>0.21</wheelSeparation>
      <wheelDiameter>0.08</wheelDiameter>
      <torque>0.01</torque>
      <commandTopic>cmd_vel</commandTopic>
      <odometryTopic>odom</odometryTopic>
      <odometryFrame>odom</odometryFrame>
      <robotBaseFrame>base_link</robotBaseFrame>
    </plugin>
  </gazebo>

  <gazebo reference="lidar_sensor">
    <sensor type="ray" name="head_hokuyo_sensor">
      <pose>0 0 0 0 0 0</pose>
      <visualize>true</visualize>
      <update_rate>20</update_rate>
      <ray>
        <scan>
          <horizontal>
            <samples>720</samples>
            <resolution>1</resolution>
            <min_angle>-1.570796</min_angle>
            <max_angle>1.570796</max_angle>
          </horizontal>
        </scan>
        <range>
          <min>0.10</min>
          <max>10.0</max>
          <resolution>0.01</resolution>
        </range>
        <noise>
          <type>gaussian</type>
          <mean>0.0</mean>
          <stddev>0.01</stddev>
        </noise>
      </ray>
      <plugin name="gazebo_ros_head_hokuyo_controller" filename="libgazebo_ros_laser.so">
        <topicName>/robot/laser/scan</topicName>
        <frameName>lidar_sensor</frameName>
      </plugin>
    </sensor>
  </gazebo>
  <!--gazebo reference="right_sensor">
    <sensor type="ray" name="right_sensor">
      <pose>0 0 0 0 0 0</pose>
      <visualize>true</visualize>
      <update_rate>10</update_rate>
      <ray>
        <scan>
          <horizontal>
            <samples>5</samples>
            <resolution>1</resolution>
            
            <min_angle>-0.2</min_angle>
            <max_angle>0.2</max_angle>
          </horizontal>
        </scan>
        <range>
          <min>0.01</min>
          <max>0.4</max>
          <resolution>0.01</resolution>
        </range>
        
      </ray>
      <plugin name="gazebo_ros_ultrasonic_controller" filename="libhector_gazebo_ros_sonar.so">
        <topicName>/distance1</topicName>
        <frameName>right_sensor</frameName>
	<gaussianNoise>0.005</gaussianNoise>
      </plugin>
    </sensor>
  </gazebo>


  <gazebo reference="left_sensor">
    <sensor type="ray" name="left_sensor">
      <pose>0 0 0 0 0 0</pose>
      <visualize>true</visualize>
      <update_rate>10</update_rate>
      <ray>
        <scan>
          <horizontal>
            <samples>5</samples>
            <resolution>1</resolution>
            
	    <min_angle>-0.2</min_angle>
            <max_angle>0.2</max_angle>
          </horizontal>
        </scan>
        <range>
          <min>0.01</min>
          <max>0.4</max>
          <resolution>0.01</resolution>
        </range>
        
      </ray>
      <plugin name="gazebo_ros_ultrasonic_controller" filename="libhector_gazebo_ros_sonar.so">
        <topicName>/distance2</topicName>
        <frameName>left_sensor</frameName>
	<gaussianNoise>0.005</gaussianNoise>
      </plugin>
    </sensor>
  </gazebo-->
  

 

  <gazebo reference="right_sensor">        
   <sensor type="ray" name="TeraRanger">
      <pose>0 0 0 0 0 0</pose>
      <visualize>true</visualize>
      <update_rate>50</update_rate>
      <ray>
         <scan>
            <horizontal>
               <samples>10</samples>
               <resolution>1</resolution> 
               <min_angle>-0.14835</min_angle>
               <max_angle>0.14835</max_angle>
            </horizontal>
            <vertical>
               <samples>10</samples>
               <resolution>1</resolution> 
               <min_angle>-0.14835</min_angle>
               <max_angle>0.14835</max_angle> 
            </vertical>
         </scan>
         <range>
            <min>0.01</min>
            <max>2</max>
            <resolution>0.02</resolution>
         </range>
      </ray>
      <plugin filename="libgazebo_ros_range.so" name="gazebo_ros_range">
         
         <alwaysOn>true</alwaysOn>
         <updateRate>50</updateRate>
         <topicName>sensor/ultrasonic_right</topicName>
         <frameName>right_sensor</frameName>
         <radiation>INFRARED</radiation>
         <fov>0.2967</fov>
      </plugin>
   </sensor>  
   </gazebo>


   <gazebo reference="left_sensor">        
   <sensor type="ray" name="TeraRanger">
      <pose>0 0 0 0 0 0</pose>
      <visualize>true</visualize>
      <update_rate>50</update_rate>
      <ray>
         <scan>
            <horizontal>
               <samples>10</samples>
               <resolution>1</resolution> 
               <min_angle>-0.14835</min_angle>
               <max_angle>0.14835</max_angle>
            </horizontal>
            <vertical>
               <samples>10</samples>
               <resolution>1</resolution> 
               <min_angle>-0.14835</min_angle>
               <max_angle>0.14835</max_angle> 
            </vertical>
         </scan>
         <range>
            <min>0.01</min>
            <max>2</max>
            <resolution>0.02</resolution>
         </range>
      </ray>
      <plugin filename="libgazebo_ros_range.so" name="gazebo_ros_range">
         
         <alwaysOn>true</alwaysOn>
         <updateRate>50</updateRate>
         <topicName>sensor/ultrasonic_left</topicName>
         <frameName>left_sensor</frameName>
         <radiation>INFRARED</radiation>
         <fov>0.2967</fov>
      </plugin>
   </sensor>  
   </gazebo>
 
    <!--link name="sonar_link" >
		<visual>
			<geometry>
				<box size=".02 .02 .02"/>
			</geometry>
			<material name="Grey" />
		</visual>
	</link>
	<joint name="sonar_joint" type="fixed">
		<origin xyz="${body_x_size/2} 0 .05" rpy="0 0 0"/>
		<parent link="base_link" />
		<child link="sonar_link" />
    	</joint>

	<link name="sonar_link_fake"/>
	<joint name="sonar_joint_fake" type="fixed">
        <origin rpy="0 ${-pi/2} 0"/>
        <parent link="sonar_link" />
        <child link="sonar_link_fake" />
	</joint-->

	

  
        <!--gazebo reference="sonar_link_fake">
            <sensor type="sonar" name="sonar">
                <always_on>1</always_on>
                <update_rate>10</update_rate>
                <visualize>true</visualize>
                <topic>sonar_scan</topic>
                <sonar>
                    <min>0.02</min>
                    <max>4.0</max>
                    <radius>15*pi/180</radius>
                </sonar>
                <plugin name="sonar_plugin_sonar" filename="libgazebo_ros_sonar.so" >
                    <gaussianNoise>0.005</gaussianNoise>
                    <topicName>sonar_scan</topicName>
                    <frameName>sonar_link</frameName>
                    <fov>15*pi/180</fov>
                </plugin>
            </sensor>
        </gazebo-->
    


	<!--gazebo>
	  <plugin name="gazebo_ros_control" filename="libgazebo_ros_control.so"/>
	</gazebo-->






















</robot>
